{
 "cells": [
  {
   "cell_type": "code",
   "execution_count": 2,
   "metadata": {},
   "outputs": [
    {
     "ename": "RuntimeError",
     "evalue": "asyncio.run() cannot be called from a running event loop",
     "output_type": "error",
     "traceback": [
      "\u001b[0;31m---------------------------------------------------------------------------\u001b[0m",
      "\u001b[0;31mRuntimeError\u001b[0m                              Traceback (most recent call last)",
      "\u001b[1;32m/Users/t-ibayashi/Workspace/TmpScripts/Study/ParallelProgram/asyncio/Day2/note.ipynb Cell 1'\u001b[0m in \u001b[0;36m<cell line: 19>\u001b[0;34m()\u001b[0m\n\u001b[1;32m     <a href='vscode-notebook-cell:/Users/t-ibayashi/Workspace/TmpScripts/Study/ParallelProgram/asyncio/Day2/note.ipynb#ch0000000?line=15'>16</a>\u001b[0m     \u001b[39mawait\u001b[39;00m task1\n\u001b[1;32m     <a href='vscode-notebook-cell:/Users/t-ibayashi/Workspace/TmpScripts/Study/ParallelProgram/asyncio/Day2/note.ipynb#ch0000000?line=16'>17</a>\u001b[0m     \u001b[39mawait\u001b[39;00m task2\n\u001b[0;32m---> <a href='vscode-notebook-cell:/Users/t-ibayashi/Workspace/TmpScripts/Study/ParallelProgram/asyncio/Day2/note.ipynb#ch0000000?line=18'>19</a>\u001b[0m asyncio\u001b[39m.\u001b[39;49mrun(main())\n",
      "File \u001b[0;32m/usr/local/Cellar/python@3.9/3.9.12/Frameworks/Python.framework/Versions/3.9/lib/python3.9/asyncio/runners.py:33\u001b[0m, in \u001b[0;36mrun\u001b[0;34m(main, debug)\u001b[0m\n\u001b[1;32m      <a href='file:///usr/local/Cellar/python%403.9/3.9.12/Frameworks/Python.framework/Versions/3.9/lib/python3.9/asyncio/runners.py?line=8'>9</a>\u001b[0m \u001b[39m\"\"\"Execute the coroutine and return the result.\u001b[39;00m\n\u001b[1;32m     <a href='file:///usr/local/Cellar/python%403.9/3.9.12/Frameworks/Python.framework/Versions/3.9/lib/python3.9/asyncio/runners.py?line=9'>10</a>\u001b[0m \n\u001b[1;32m     <a href='file:///usr/local/Cellar/python%403.9/3.9.12/Frameworks/Python.framework/Versions/3.9/lib/python3.9/asyncio/runners.py?line=10'>11</a>\u001b[0m \u001b[39mThis function runs the passed coroutine, taking care of\u001b[39;00m\n\u001b[0;32m   (...)\u001b[0m\n\u001b[1;32m     <a href='file:///usr/local/Cellar/python%403.9/3.9.12/Frameworks/Python.framework/Versions/3.9/lib/python3.9/asyncio/runners.py?line=29'>30</a>\u001b[0m \u001b[39m    asyncio.run(main())\u001b[39;00m\n\u001b[1;32m     <a href='file:///usr/local/Cellar/python%403.9/3.9.12/Frameworks/Python.framework/Versions/3.9/lib/python3.9/asyncio/runners.py?line=30'>31</a>\u001b[0m \u001b[39m\"\"\"\u001b[39;00m\n\u001b[1;32m     <a href='file:///usr/local/Cellar/python%403.9/3.9.12/Frameworks/Python.framework/Versions/3.9/lib/python3.9/asyncio/runners.py?line=31'>32</a>\u001b[0m \u001b[39mif\u001b[39;00m events\u001b[39m.\u001b[39m_get_running_loop() \u001b[39mis\u001b[39;00m \u001b[39mnot\u001b[39;00m \u001b[39mNone\u001b[39;00m:\n\u001b[0;32m---> <a href='file:///usr/local/Cellar/python%403.9/3.9.12/Frameworks/Python.framework/Versions/3.9/lib/python3.9/asyncio/runners.py?line=32'>33</a>\u001b[0m     \u001b[39mraise\u001b[39;00m \u001b[39mRuntimeError\u001b[39;00m(\n\u001b[1;32m     <a href='file:///usr/local/Cellar/python%403.9/3.9.12/Frameworks/Python.framework/Versions/3.9/lib/python3.9/asyncio/runners.py?line=33'>34</a>\u001b[0m         \u001b[39m\"\u001b[39m\u001b[39masyncio.run() cannot be called from a running event loop\u001b[39m\u001b[39m\"\u001b[39m)\n\u001b[1;32m     <a href='file:///usr/local/Cellar/python%403.9/3.9.12/Frameworks/Python.framework/Versions/3.9/lib/python3.9/asyncio/runners.py?line=35'>36</a>\u001b[0m \u001b[39mif\u001b[39;00m \u001b[39mnot\u001b[39;00m coroutines\u001b[39m.\u001b[39miscoroutine(main):\n\u001b[1;32m     <a href='file:///usr/local/Cellar/python%403.9/3.9.12/Frameworks/Python.framework/Versions/3.9/lib/python3.9/asyncio/runners.py?line=36'>37</a>\u001b[0m     \u001b[39mraise\u001b[39;00m \u001b[39mValueError\u001b[39;00m(\u001b[39m\"\u001b[39m\u001b[39ma coroutine was expected, got \u001b[39m\u001b[39m{!r}\u001b[39;00m\u001b[39m\"\u001b[39m\u001b[39m.\u001b[39mformat(main))\n",
      "\u001b[0;31mRuntimeError\u001b[0m: asyncio.run() cannot be called from a running event loop"
     ]
    }
   ],
   "source": [
    "import asyncio\n",
    "\n",
    "async def func1():\n",
    "    print('func1() started')\n",
    "    await asyncio.sleep(1)\n",
    "    print('func1() finished')\n",
    "\n",
    "async def func2():\n",
    "    print('func2() started')\n",
    "    await asyncio.sleep(1)\n",
    "    print('func2() finished')\n",
    "\n",
    "async def main():\n",
    "    task1 = asyncio.create_task(func1())\n",
    "    task2 = asyncio.create_task(func2())\n",
    "    await task1\n",
    "    await task2\n",
    "\n",
    "asyncio.run(main())"
   ]
  }
 ],
 "metadata": {
  "interpreter": {
   "hash": "aee8b7b246df8f9039afb4144a1f6fd8d2ca17a180786b69acc140d282b71a49"
  },
  "kernelspec": {
   "display_name": "Python 3.9.12 64-bit",
   "language": "python",
   "name": "python3"
  },
  "language_info": {
   "codemirror_mode": {
    "name": "ipython",
    "version": 3
   },
   "file_extension": ".py",
   "mimetype": "text/x-python",
   "name": "python",
   "nbconvert_exporter": "python",
   "pygments_lexer": "ipython3",
   "version": "3.9.12"
  },
  "orig_nbformat": 4
 },
 "nbformat": 4,
 "nbformat_minor": 2
}
